<?xml version="1.0" ?>
<!-- =================================================================================== -->
<!-- |    This document was autogenerated by xacro from our_ur5_modified.urdf.xacro    | -->
<!-- |    EDITING THIS FILE BY HAND IS NOT RECOMMENDED                                 | -->
<!-- =================================================================================== -->
<robot name="our_ur5">
  <!-- <xacro:property name="" value="${pi/2}" /> -->
  <!-- <robot name="our_ur5"> -->
  <!-- Links -->
  <link name="base_link"/>
  <joint name="base_joint" type="revolute">
    <parent link="base_link"/>
    <child link="base"/>
    <axis xyz="0.0 0.0 1"/>
    <limit effort="100.0" lower="-6.283185307179586" upper="6.283185307179586" velocity="3.15"/>
    <origin rpy="0 0 0" xyz="0 0 0"/>
  </joint>
  <link name="base">
    <visual>
      <origin rpy="0 0 0" xyz="0 0 0.1"/>
      <geometry>
        <cylinder length="0.2" radius="0.08"/>
      </geometry>
      <material name="gray">
        <color rgba="0.8 0.8 0.8 1.0"/>
      </material>
    </visual>
  </link>
  <joint name="base_shoulder" type="revolute">
    <parent link="base"/>
    <child link="shoulder"/>
    <axis xyz="0.0 1 0.0"/>
    <limit effort="100.0" lower="-6.283185307179586" upper="6.283185307179586" velocity="3.15"/>
    <origin rpy="0 0 0" xyz="0 -0.16 0.0892"/>
  </joint>
  <link name="shoulder">
    <visual>
      <origin rpy="0 0 0" xyz="0 0 0.25"/>
      <geometry>
        <cylinder length="0.5" radius="0.08"/>
      </geometry>
      <material name="gray">
        <color rgba="0.8 0.8 0.8 1.0"/>
      </material>
    </visual>
  </link>
  <joint name="shoulder_elbow" type="revolute">
    <parent link="shoulder"/>
    <child link="elbow"/>
    <axis xyz="0.0 1 0.0"/>
    <limit effort="100.0" lower="-3.141592653589793" upper="3.141592653589793" velocity="3.15"/>
    <origin rpy="0 0 0" xyz="0 0.16 0.425"/>
  </joint>
  <link name="elbow">
    <visual>
      <origin rpy="0 0 0" xyz="0 0 0.196"/>
      <geometry>
        <cylinder length="0.392" radius="0.08"/>
      </geometry>
      <material name="gray">
        <color rgba="0.8 0.8 0.8 1.0"/>
      </material>
    </visual>
  </link>
  <joint name="elbow_wrist1" type="revolute">
    <parent link="elbow"/>
    <child link="wrist1"/>
    <axis xyz="0.0 1 0.0"/>
    <limit effort="100" lower="-6.283185307179586" upper="6.283185307179586" velocity="3.2"/>
    <origin rpy="0 0 0" xyz="0 0 0.392"/>
  </joint>
  <link name="wrist1">
    <visual>
      <origin rpy="1.5707963267948966 0 0" xyz="0 0.05 0"/>
      <geometry>
        <cylinder length="0.24" radius="0.08"/>
      </geometry>
      <material name="gray">
        <color rgba="0.8 0.8 0.8 1.0"/>
      </material>
    </visual>
  </link>
  <joint name="wrist1_wrist2" type="revolute">
    <parent link="wrist1"/>
    <child link="wrist2"/>
    <axis xyz="0.0 0.0 1"/>
    <limit effort="100" lower="-6.283185307179586" upper="6.283185307179586" velocity="3.2"/>
    <origin rpy="0 0 0" xyz="0 -0.1093 0"/>
  </joint>
  <link name="wrist2">
    <visual>
      <origin rpy="0 0 0" xyz="0 0 -0.08"/>
      <geometry>
        <cylinder length="0.32" radius="0.08"/>
      </geometry>
      <material name="gray">
        <color rgba="0.8 0.8 0.8 1.0"/>
      </material>
    </visual>
  </link>
  <joint name="wrist2_wrist3" type="revolute">
    <parent link="wrist2"/>
    <child link="wrist3"/>
    <axis xyz="0.0 0 1"/>
    <limit effort="100" lower="-6.283185307179586" upper="6.283185307179586" velocity="3.2"/>
    <origin rpy="1.5707963267948966 0 0" xyz="0 -0.0825 0.09475"/>
  </joint>
  <link name="wrist3">
    <visual>
      <origin rpy="0 0 0" xyz="0 0 0"/>
      <geometry>
        <cylinder length="0.08" radius="0.08"/>
      </geometry>
      <material name="gray">
        <color rgba="0.8 0.8 0.8 1.0"/>
      </material>
    </visual>
  </link>
</robot>

